{
 "cells": [
  {
   "cell_type": "code",
   "execution_count": 2,
   "metadata": {},
   "outputs": [],
   "source": [
    "import keras\n",
    "import pandas as pd"
   ]
  },
  {
   "cell_type": "code",
   "execution_count": 3,
   "metadata": {},
   "outputs": [],
   "source": [
    "x_train = pd.read_csv('Dataset_x_train_suavizante.csv')\n",
    "y_train = pd.read_csv('Dataset_y_train_suavizante.csv')\n",
    "x_test = pd.read_csv('Dataset_x_test_suavizante.csv')\n",
    "y_test = pd.read_csv('Dataset_y_test_suavizante.csv')"
   ]
  },
  {
   "cell_type": "code",
   "execution_count": 4,
   "metadata": {},
   "outputs": [
    {
     "name": "stdout",
     "output_type": "stream",
     "text": [
      "Epoch 1/10\n"
     ]
    },
    {
     "ename": "ValueError",
     "evalue": "in user code:\n\n    File \"/Users/joseoviedo/Documents/Vision-Artificial/venv/lib/python3.9/site-packages/keras/engine/training.py\", line 1284, in train_function  *\n        return step_function(self, iterator)\n    File \"/Users/joseoviedo/Documents/Vision-Artificial/venv/lib/python3.9/site-packages/keras/engine/training.py\", line 1268, in step_function  **\n        outputs = model.distribute_strategy.run(run_step, args=(data,))\n    File \"/Users/joseoviedo/Documents/Vision-Artificial/venv/lib/python3.9/site-packages/keras/engine/training.py\", line 1249, in run_step  **\n        outputs = model.train_step(data)\n    File \"/Users/joseoviedo/Documents/Vision-Artificial/venv/lib/python3.9/site-packages/keras/engine/training.py\", line 1051, in train_step\n        loss = self.compute_loss(x, y, y_pred, sample_weight)\n    File \"/Users/joseoviedo/Documents/Vision-Artificial/venv/lib/python3.9/site-packages/keras/engine/training.py\", line 1109, in compute_loss\n        return self.compiled_loss(\n    File \"/Users/joseoviedo/Documents/Vision-Artificial/venv/lib/python3.9/site-packages/keras/engine/compile_utils.py\", line 265, in __call__\n        loss_value = loss_obj(y_t, y_p, sample_weight=sw)\n    File \"/Users/joseoviedo/Documents/Vision-Artificial/venv/lib/python3.9/site-packages/keras/losses.py\", line 142, in __call__\n        losses = call_fn(y_true, y_pred)\n    File \"/Users/joseoviedo/Documents/Vision-Artificial/venv/lib/python3.9/site-packages/keras/losses.py\", line 268, in call  **\n        return ag_fn(y_true, y_pred, **self._fn_kwargs)\n    File \"/Users/joseoviedo/Documents/Vision-Artificial/venv/lib/python3.9/site-packages/keras/losses.py\", line 1984, in categorical_crossentropy\n        return backend.categorical_crossentropy(\n    File \"/Users/joseoviedo/Documents/Vision-Artificial/venv/lib/python3.9/site-packages/keras/backend.py\", line 5559, in categorical_crossentropy\n        target.shape.assert_is_compatible_with(output.shape)\n\n    ValueError: Shapes (32, 1) and (32, 2) are incompatible\n",
     "output_type": "error",
     "traceback": [
      "\u001b[0;31m---------------------------------------------------------------------------\u001b[0m",
      "\u001b[0;31mValueError\u001b[0m                                Traceback (most recent call last)",
      "Cell \u001b[0;32mIn[4], line 12\u001b[0m\n\u001b[1;32m     10\u001b[0m model\u001b[39m.\u001b[39mcompile(optimizer\u001b[39m=\u001b[39m\u001b[39m'\u001b[39m\u001b[39madam\u001b[39m\u001b[39m'\u001b[39m, loss\u001b[39m=\u001b[39m\u001b[39m'\u001b[39m\u001b[39mcategorical_crossentropy\u001b[39m\u001b[39m'\u001b[39m, metrics\u001b[39m=\u001b[39m[\u001b[39m'\u001b[39m\u001b[39maccuracy\u001b[39m\u001b[39m'\u001b[39m])\n\u001b[1;32m     11\u001b[0m \u001b[39m# Train the model\u001b[39;00m\n\u001b[0;32m---> 12\u001b[0m model\u001b[39m.\u001b[39;49mfit(x_train, y_train, epochs\u001b[39m=\u001b[39;49m\u001b[39m10\u001b[39;49m)\n\u001b[1;32m     13\u001b[0m \u001b[39m# Evaluate the model\u001b[39;00m\n\u001b[1;32m     14\u001b[0m model\u001b[39m.\u001b[39mevaluate(x_test, y_test)\n",
      "File \u001b[0;32m~/Documents/Vision-Artificial/venv/lib/python3.9/site-packages/keras/utils/traceback_utils.py:70\u001b[0m, in \u001b[0;36mfilter_traceback.<locals>.error_handler\u001b[0;34m(*args, **kwargs)\u001b[0m\n\u001b[1;32m     67\u001b[0m     filtered_tb \u001b[39m=\u001b[39m _process_traceback_frames(e\u001b[39m.\u001b[39m__traceback__)\n\u001b[1;32m     68\u001b[0m     \u001b[39m# To get the full stack trace, call:\u001b[39;00m\n\u001b[1;32m     69\u001b[0m     \u001b[39m# `tf.debugging.disable_traceback_filtering()`\u001b[39;00m\n\u001b[0;32m---> 70\u001b[0m     \u001b[39mraise\u001b[39;00m e\u001b[39m.\u001b[39mwith_traceback(filtered_tb) \u001b[39mfrom\u001b[39;00m \u001b[39mNone\u001b[39;00m\n\u001b[1;32m     71\u001b[0m \u001b[39mfinally\u001b[39;00m:\n\u001b[1;32m     72\u001b[0m     \u001b[39mdel\u001b[39;00m filtered_tb\n",
      "File \u001b[0;32m/var/folders/fh/8mm2vsvs5ms6dc4lcrw1b8x80000gn/T/__autograph_generated_filee376hzz2.py:15\u001b[0m, in \u001b[0;36mouter_factory.<locals>.inner_factory.<locals>.tf__train_function\u001b[0;34m(iterator)\u001b[0m\n\u001b[1;32m     13\u001b[0m \u001b[39mtry\u001b[39;00m:\n\u001b[1;32m     14\u001b[0m     do_return \u001b[39m=\u001b[39m \u001b[39mTrue\u001b[39;00m\n\u001b[0;32m---> 15\u001b[0m     retval_ \u001b[39m=\u001b[39m ag__\u001b[39m.\u001b[39mconverted_call(ag__\u001b[39m.\u001b[39mld(step_function), (ag__\u001b[39m.\u001b[39mld(\u001b[39mself\u001b[39m), ag__\u001b[39m.\u001b[39mld(iterator)), \u001b[39mNone\u001b[39;00m, fscope)\n\u001b[1;32m     16\u001b[0m \u001b[39mexcept\u001b[39;00m:\n\u001b[1;32m     17\u001b[0m     do_return \u001b[39m=\u001b[39m \u001b[39mFalse\u001b[39;00m\n",
      "\u001b[0;31mValueError\u001b[0m: in user code:\n\n    File \"/Users/joseoviedo/Documents/Vision-Artificial/venv/lib/python3.9/site-packages/keras/engine/training.py\", line 1284, in train_function  *\n        return step_function(self, iterator)\n    File \"/Users/joseoviedo/Documents/Vision-Artificial/venv/lib/python3.9/site-packages/keras/engine/training.py\", line 1268, in step_function  **\n        outputs = model.distribute_strategy.run(run_step, args=(data,))\n    File \"/Users/joseoviedo/Documents/Vision-Artificial/venv/lib/python3.9/site-packages/keras/engine/training.py\", line 1249, in run_step  **\n        outputs = model.train_step(data)\n    File \"/Users/joseoviedo/Documents/Vision-Artificial/venv/lib/python3.9/site-packages/keras/engine/training.py\", line 1051, in train_step\n        loss = self.compute_loss(x, y, y_pred, sample_weight)\n    File \"/Users/joseoviedo/Documents/Vision-Artificial/venv/lib/python3.9/site-packages/keras/engine/training.py\", line 1109, in compute_loss\n        return self.compiled_loss(\n    File \"/Users/joseoviedo/Documents/Vision-Artificial/venv/lib/python3.9/site-packages/keras/engine/compile_utils.py\", line 265, in __call__\n        loss_value = loss_obj(y_t, y_p, sample_weight=sw)\n    File \"/Users/joseoviedo/Documents/Vision-Artificial/venv/lib/python3.9/site-packages/keras/losses.py\", line 142, in __call__\n        losses = call_fn(y_true, y_pred)\n    File \"/Users/joseoviedo/Documents/Vision-Artificial/venv/lib/python3.9/site-packages/keras/losses.py\", line 268, in call  **\n        return ag_fn(y_true, y_pred, **self._fn_kwargs)\n    File \"/Users/joseoviedo/Documents/Vision-Artificial/venv/lib/python3.9/site-packages/keras/losses.py\", line 1984, in categorical_crossentropy\n        return backend.categorical_crossentropy(\n    File \"/Users/joseoviedo/Documents/Vision-Artificial/venv/lib/python3.9/site-packages/keras/backend.py\", line 5559, in categorical_crossentropy\n        target.shape.assert_is_compatible_with(output.shape)\n\n    ValueError: Shapes (32, 1) and (32, 2) are incompatible\n"
     ]
    }
   ],
   "source": [
    "# Define the input layer\n",
    "input_layer = keras.layers.Input(shape=(39,))\n",
    "# Define the hidden layer\n",
    "hidden_layer = keras.layers.Dense(128, activation='relu')(input_layer)\n",
    "# Define the output layer\n",
    "output_layer = keras.layers.Dense(2, activation='softmax')(hidden_layer)\n",
    "# Create the model\n",
    "model = keras.models.Model(input_layer, output_layer)\n",
    "# Compile the model\n",
    "model.compile(optimizer='adam', loss='categorical_crossentropy', metrics=['accuracy'])\n",
    "# Train the model\n",
    "model.fit(x_train, y_train, epochs=10)\n",
    "# Evaluate the model\n",
    "model.evaluate(x_test, y_test)"
   ]
  }
 ],
 "metadata": {
  "kernelspec": {
   "display_name": "venv",
   "language": "python",
   "name": "python3"
  },
  "language_info": {
   "codemirror_mode": {
    "name": "ipython",
    "version": 3
   },
   "file_extension": ".py",
   "mimetype": "text/x-python",
   "name": "python",
   "nbconvert_exporter": "python",
   "pygments_lexer": "ipython3",
   "version": "3.9.16"
  },
  "orig_nbformat": 4
 },
 "nbformat": 4,
 "nbformat_minor": 2
}
